Workbook

Sheet MC
B2: P E T R O L E O B R A S I L E I R O S. A. P E T R O B R A S
B3: M E M Ó R I A D E C Á L C U L O D E M E D I Ç Ã O
B4: Razão Social: | D4: PA ARQUIVOS LTDA | I4: CNPJ: | J4: 34.409.656/0001-84 | L4: Item 1 PPU | M4: IAPEFARQ: | N4: 0
B5: Contrato SAP: | D5: 4600687006 | I5: Área contrato: | J5: Lote 2 | M5: FDM: | N5: 0
B6: Objeto: | D6: Serviços de guarda e gerenciamento de documentos e informações do acervo da PETROBRAS | I6: Instr. contratual: | J6: 5900.0133214.25.2 | L6: Item 2 PPU | M6: IAPEFARQ: | N6: 0
I7: Período: | J7: 00/00/0000 à 00/00/0000 | M7: FDM: | N7: 0
C10: Item | D10: Descrição da atividade | I10: Unidade | J10: QExec | K10: QFinal | L10: Valor unitário | M10: Valor total a pagar | N10: Observações
C11: 1 | D11: Guarda de Documentos e Informações
D12: ARM-CX-DOC: Armazenamento de caixas para documentos
C13: 1.1 | D13: QUAm-1 | E13: QBm | F13: QDm | G13: QNm | H13: QUAm | I13: UA | J13: =SUMIF(ARM!K:K,"ARM-CX-DOC",ARM!J:J) -> 0 | K13: =J13*$N$5 -> 0 | L13: 0.9 | M13: =K13*L13 -> 0
D14: =SUMIF(ARM!K:K,"ARM-CX-DOC",ARM!D:D) -> 0 | E14: =SUMIF(ARM!K:K,"ARM-CX-DOC",ARM!E:E) -> 0 | F14: =SUMIF(ARM!K:K,"ARM-CX-DOC",ARM!F:F) -> 0 | G14: =SUMIF(ARM!K:K,"ARM-CX-DOC",ARM!G:G) -> 0 | H14: =D14-((E14+F14)-G14) -> 0
D15: ARM-CX-MID: Armazenamento de caixas para mídias
C16: 1.2 | D16: QUAm-1 | E16: QBm | F16: QDm | G16: QNm | H16: QUAm | I16: UA | J16: =SUMIF(ARM!K:K,"ARM-CX-MID",ARM!J:J) -> 0 | K16: =J16*$N$5 -> 0 | L16: 0.9 | M16: =K16*L16 -> 0
D17: =SUMIF(ARM!K:K,"ARM-CX-MID",ARM!D:D) -> 0 | E17: =SUMIF(ARM!K:K,"ARM-CX-MID",ARM!E:E) -> 0 | F17: =SUMIF(ARM!K:K,"ARM-CX-MID",ARM!F:F) -> 0 | G17: =SUMIF(ARM!K:K,"ARM-CX-MID",ARM!G:G) -> 0 | H17: =D17-((E17+F17)-G17) -> 0
D18: ARM-TB: Armazenamento de tubos
C19: 1.3 | D19: QUAm-1 | E19: QBm | F19: QDm | G19: QNm | H19: QUAm | I19: UA | J19: =SUMIF(ARM!K:K,"ARM-TB",ARM!J:J) -> 0 | K19: =J19*$N$5 -> 0 | L19: 0.9 | M19: =K19*L19 -> 0
D20: =SUMIF(ARM!K:K,"ARM-TB",ARM!D:D) -> 0 | E20: =SUMIF(ARM!K:K,"ARM-TB",ARM!E:E) -> 0 | F20: =SUMIF(ARM!K:K,"ARM-TB",ARM!F:F) -> 0 | G20: =SUMIF(ARM!K:K,"ARM-TB",ARM!G:G) -> 0 | H20: =D20-((E20+F20)-G20) -> 0
D21: ARM-MA: Armazenamento de mapotecas e arquivos de aço
C22: 1.4 | D22: QUAm-1 | E22: QBm | F22: QDm | G22: QNm | H22: QUAm | I22: UA | J22: =SUMIF(ARM!K:K,"ARM-MA",ARM!J:J) -> 0 | K22: =J22*$N$5 -> 0 | L22: 70 | M22: =K22*L22 -> 0
D23: =SUMIF(ARM!K:K,"ARM-MA",ARM!D:D) -> 0 | E23: =SUMIF(ARM!K:K,"ARM-MA",ARM!E:E) -> 0 | F23: =SUMIF(ARM!K:K,"ARM-MA",ARM!F:F) -> 0 | G23: =SUMIF(ARM!K:K,"ARM-MA",ARM!G:G) -> 0 | H23: =D23-((E23+F23)-G23) -> 0
D24: ARM-MIC: Armazenamento de microformas
C25: 1.5 | D25: QUAm-1 | E25: QBm | F25: QDm | G25: QNm | H25: QUAm | I25: UA | J25: =SUMIF(ARM!K:K,"ARM-MIC",ARM!J:J) -> 0 | K25: =J25*$N$5 -> 0 | L25: 0.1 | M25: =K25*L25 -> 0
D26: =SUMIF(ARM!K:K,"ARM-MIC",ARM!D:D) -> 0 | E26: =SUMIF(ARM!K:K,"ARM-MIC",ARM!E:E) -> 0 | F26: =SUMIF(ARM!K:K,"ARM-MIC",ARM!F:F) -> 0 | G26: =SUMIF(ARM!K:K,"ARM-MIC",ARM!G:G) -> 0 | H26: =D26-((E26+F26)-G26) -> 0
D27: ARM-MID: Armazenamento de midias
C28: 1.6 | D28: QUAm-1 | E28: QBm | F28: QDm | G28: QNm | H28: QUAm | I28: UA | J28: =SUMIF(ARM!K:K,"ARM-MID",ARM!J:J) -> 0 | K28: =J28*$N$5 -> 0 | L28: 0.1 | M28: =K28*L28 -> 0
D29: =SUMIF(ARM!K:K,"ARM-MID",ARM!D:D) -> 0 | E29: =SUMIF(ARM!K:K,"ARM-MID",ARM!E:E) -> 0 | F29: =SUMIF(ARM!K:K,"ARM-MID",ARM!F:F) -> 0 | G29: =SUMIF(ARM!K:K,"ARM-MID",ARM!G:G) -> 0 | H29: =D29-((E29+F29)-G29) -> 0
C30: 1.7 | D30: FRE-NRM: Frete normal | I30: Frete | J30: =SUMIF(DADOS!AE:AE,LEFT(D30,SEARCH(":",D30)-1),DADOS!AH:AH) -> 0 | K30: =J30*$N$5 -> 0 | L30: 50 | M30: =K30*L30 -> 0
C31: 1.8 | D31: FRE-EXP: Frete expresso | I31: Frete | J31: =SUMIF(DADOS!AE:AE,LEFT(D31,SEARCH(":",D31)-1),DADOS!AH:AH) -> 0 | K31: =J31*$N$5 -> 0 | L31: 100 | M31: =K31*L31 -> 0
C32: 1.9 | D32: KM-AD: Quilometragem adicional | I32: KM | J32: =SUM(DADOS!Y:Y) -> 0 | K32: =J32*$N$5 -> 0 | L32: 1 | M32: =K32*L32 -> 0
C33: 1.10 | D33: PES-ITEM: Pesquisa de itens avulsos | I33: Item Avulso | J33: =SUMIF(DADOS!AE:AE,LEFT(D33,SEARCH(":",D33)-1),DADOS!AH:AH) -> 0 | K33: =J33*$N$5 -> 0 | L33: 3 | M33: =K33*L33 -> 0
C34: 1.11 | D34: DES-EMB: Destruição segura de documentos | I34: Embalagem | J34: =SUMIF(DADOS!AE:AE,LEFT(D34,SEARCH(":",D34)-1),DADOS!AH:AH) -> 0 | K34: =J34*$N$5 -> 0 | L34: 3 | M34: =K34*L34 -> 0
C35: 1.12 | D35: TRANSF: Transferência inicial de acervo documental | I35: Transferência | J35: =SUMIF(DADOS!AE:AE,LEFT(D35,SEARCH(":",D35)-1),DADOS!AH:AH) -> 0 | K35: =J35*$N$5 -> 0 | L35: 100000 | M35: =K35*L35 -> 0
C36: 1.13 | D36: MIGR-UA: Migração de acervo documental para digitalização | I36: UA | J36: =SUMIF(DADOS!AE:AE,LEFT(D36,SEARCH(":",D36)-1),DADOS!AH:AH) -> 0 | K36: =J36 -> 0 | L36: 7.5 | M36: =K36*L36 -> 0
C37: 2 | D37: Gerenciamento de Documentos e Informações
C38: 2.1 | D38: CAT-ITEM: Catalogação de documentos digitalizados | I38: Documento | J38: =SUMIF(DADOS!AE:AE,LEFT(D38,SEARCH(":",D38)-1),DADOS!AH:AH) -> 0 | K38: =J38*$N$7 -> 0 | L38: 0.2 | M38: =K38*L38 -> 0
C39: 2.2 | D39: ORG-DOC: Organização de documentos para digitalização | I39: UA | J39: =SUMIF(DADOS!AE:AE,LEFT(D39,SEARCH(":",D39)-1),DADOS!AH:AH) -> 0 | K39: =J39*$N$7 -> 0 | L39: 10 | M39: =K39*L39 -> 0
C40: 2.3 | D40: DIG-MI: Digitalização de microfilmes | I40: UD | J40: =SUMIF(DADOS!AE:AE,LEFT(D40,SEARCH(":",D40)-1),DADOS!AH:AH) -> 0 | K40: =J40*$N$7 -> 0 | L40: 0.05 | M40: =K40*L40 -> 0
C41: 2.4 | D41: DIG-MF: Digitalização de microfichas | I41: UD | J41: =SUMIF(DADOS!AE:AE,LEFT(D41,SEARCH(":",D41)-1),DADOS!AH:AH) -> 0 | K41: =J41*$N$7 -> 0 | L41: 0.05 | M41: =K41*L41 -> 0
C42: 2.5 | D42: DIG-DOC: Digitalização de documentos | I42: UD | J42: =SUMIF(DADOS!AE:AE,LEFT(D42,SEARCH(":",D42)-1),DADOS!AH:AH) -> 0 | K42: =J42*$N$7 -> 0 | L42: 0.11 | M42: =K42*L42 -> 0
C43: 2.6 | D43: IND-DOC: Indexação de documentos | I43: UD | J43: =SUMIF(DADOS!AE:AE,LEFT(D43,SEARCH(":",D43)-1),DADOS!AH:AH) -> 0 | K43: =J43*$N$7 -> 0 | L43: 0.1 | M43: =K43*L43 -> 0
...

Sheet ARM
A1: Contrato-Reg. | B1: Lotação | C1: Item | D1: QUAm-1 | E1: QBm | F1: QDm | G1: QNm | H1: QUAm | I1: FC | J1: QUA | K1: Linha de serviço PPU

Sheet DADOS
B1: DADOS DO CONTRATO | D1: DADOS DO CLIENTE | I1: DADOS DA GUARDA EXTERNA | N1: DADOS DA FISCALIZAÇÃO | S1: DADOS DA LOCALIZAÇÃO (IMÓVEL PETROBRAS) | V1: DADOS DA LOCALIZAÇÃO (GALPÃO GUARDA EXTERNA) | Y1: DADOS DA MEDIÇÃO | AF1: Formula
B2: Descrição da atividade | C2: Item | D2: Aplicação | E2: Código da solicitação | F2: D. solicitação | G2: Gerência solicitante | H2: Qtd. | I2: Código OS | J2: D. abertura | K2: D. fechamento | L2: Prazo combinado | M2: Qtd. | N2: Agrupamento | O2: Classificação | P2: FDM | Q2: Obs. Isenção | R2: FA | S2: Localidade | T2: Município | U2: UF | V2: Localidade | W2: Município | X2: UF | Y2: KM | Z2: FC | AA2: QExec | AB2: Unidade | AC2: Centro | AD2: Código Centro | AE2: Linha de serviço PPU 1 | AF2: Identificador | AG2: Contador | AH2: Novo QExec
AF3: =IF(B3="","",TEXT(J3,"DD/MM/AA")&"_"&S3&"_"&V3) | AG3: =IF(AF3="","",COUNTIF(AF3:AF$3000,AF3)) | AH3: =IF(AA3="","", IF(AG3>1,"", IF(SUMIF(AF$3:AF$31,AF3,H$3:H$31)/10<1,1,SUMIF(AF$3:AF$31,AF3,H$3:H$31)/10)))
AF4: =IF(B4="","",TEXT(J4,"DD/MM/AA")&"_"&S4&"_"&V4) | AG4: =IF(AF4="","",COUNTIF(AF4:AF$3000,AF4)) | AH4: =IF(AA4="","", IF(AG4>1,"", IF(SUMIF(AF$3:AF$31,AF4,H$3:H$31)/10<1,1,SUMIF(AF$3:AF$31,AF4,H$3:H$31)/10)))
AF5: =IF(B5="","",TEXT(J5,"DD/MM/AA")&"_"&S5&"_"&V5) | AG5: =IF(AF5="","",COUNTIF(AF5:AF$3000,AF5)) | AH5: =IF(AA5="","", IF(AG5>1,"", IF(SUMIF(AF$3:AF$31,AF5,H$3:H$31)/10<1,1,SUMIF(AF$3:AF$31,AF5,H$3:H$31)/10)))
AF6: =IF(B6="","",TEXT(J6,"DD/MM/AA")&"_"&S6&"_"&V6) | AG6: =IF(AF6="","",COUNTIF(AF6:AF$3000,AF6)) | AH6: =IF(AA6="","", IF(AG6>1,"", IF(SUMIF(AF$3:AF$31,AF6,H$3:H$31)/10<1,1,SUMIF(AF$3:AF$31,AF6,H$3:H$31)/10)))
AF7: =IF(B7="","",TEXT(J7,"DD/MM/AA")&"_"&S7&"_"&V7) | AG7: =IF(AF7="","",COUNTIF(AF7:AF$3000,AF7)) | AH7: =IF(AA7="","", IF(AG7>1,"", IF(SUMIF(AF$3:AF$31,AF7,H$3:H$31)/10<1,1,SUMIF(AF$3:AF$31,AF7,H$3:H$31)/10)))
AF8: =IF(B8="","",TEXT(J8,"DD/MM/AA")&"_"&S8&"_"&V8) | AG8: =IF(AF8="","",COUNTIF(AF8:AF$3000,AF8)) | AH8: =IF(AA8="","", IF(AG8>1,"", IF(SUMIF(AF$3:AF$31,AF8,H$3:H$31)/10<1,1,SUMIF(AF$3:AF$31,AF8,H$3:H$31)/10)))
AF9: =IF(B9="","",TEXT(J9,"DD/MM/AA")&"_"&S9&"_"&V9) | AG9: =IF(AF9="","",COUNTIF(AF9:AF$3000,AF9)) | AH9: =IF(AA9="","", IF(AG9>1,"", IF(SUMIF(AF$3:AF$31,AF9,H$3:H$31)/10<1,1,SUMIF(AF$3:AF$31,AF9,H$3:H$31)/10)))
AF10: =IF(B10="","",TEXT(J10,"DD/MM/AA")&"_"&S10&"_"&V10) | AG10: =IF(AF10="","",COUNTIF(AF10:AF$3000,AF10)) | AH10: =IF(AA10="","", IF(AG10>1,"", IF(SUMIF(AF$3:AF$31,AF10,H$3:H$31)/10<1,1,SUMIF(AF$3:AF$31,AF10,H$3:H$31)/10)))
AF11: =IF(B11="","",TEXT(J11,"DD/MM/AA")&"_"&S11&"_"&V11) | AG11: =IF(AF11="","",COUNTIF(AF11:AF$3000,AF11)) | AH11: =IF(AA11="","", IF(AG11>1,"", IF(SUMIF(AF$3:AF$31,AF11,H$3:H$31)/10<1,1,SUMIF(AF$3:AF$31,AF11,H$3:H$31)/10)))
AF12: =IF(B12="","",TEXT(J12,"DD/MM/AA")&"_"&S12&"_"&V12) | AG12: =IF(AF12="","",COUNTIF(AF12:AF$3000,AF12)) | AH12: =IF(AA12="","", IF(AG12>1,"", IF(SUMIF(AF$3:AF$31,AF12,H$3:H$31)/10<1,1,SUMIF(AF$3:AF$31,AF12,H$3:H$31)/10)))
AF13: =IF(B13="","",TEXT(J13,"DD/MM/AA")&"_"&S13&"_"&V13) | AG13: =IF(AF13="","",COUNTIF(AF13:AF$3000,AF13)) | AH13: =IF(AA13="","", IF(AG13>1,"", IF(SUMIF(AF$3:AF$31,AF13,H$3:H$31)/10<1,1,SUMIF(AF$3:AF$31,AF13,H$3:H$31)/10)))
AF14: =IF(B14="","",TEXT(J14,"DD/MM/AA")&"_"&S14&"_"&V14) | AG14: =IF(AF14="","",COUNTIF(AF14:AF$3000,AF14)) | AH14: =IF(AA14="","", IF(AG14>1,"", IF(SUMIF(AF$3:AF$31,AF14,H$3:H$31)/10<1,1,SUMIF(AF$3:AF$31,AF14,H$3:H$31)/10)))
... AF1000: =IF(B1000="","",TEXT(J1000,"DD/MM/AA")&"_"&S1000&"_"&V1000) | AG1000: =IF(AF1000="","",COUNTIF(AF1000:AF$3000,AF1000)) | AH1000: =IF(AA1000="","", IF(AG1000>1,"", IF(SUMIF(AF$3:AF$31,AF1000,H$3:H$31)/10<1,1,SUMIF(AF$3:AF$31,AF1000,H$3:H$31)/10)))

Sheet MEDICAO
J2: Valor total | K2: =SUBTOTAL(9,K4:K10000) -> 0
B3: Estado | C3: Centro#Cód. Centro | D3: Decrição da atividade | E3: Item PPU | F3: Linha de serviço PPU | G3: Qexec | H3: FDM | I3: Qfinal | J3: Valor unitário | K3: Subtotal

Sheet Obs
B2: Planilha Dados1 (Serão os dados do painel de controle)
B3: - Referência dos modelos de memória de cálculo dos contratos anteriores
B4: - Juntar as informações das planilhasControleDeOS e FreteConsolidado
B6: Planilha Dados2: dados para medição
B7: - Ter um quadro com a divisão das medições de frete separadas por região ou estado
B9: - Inserir um quadro com índice de siglas
B11: Dados de medição do contrato
C12: Inserir as fórmulas de cálculo
B15: QUAFCN = Ʃ [QItemFCN x FCFCN]
B18: QUAm = QUAm-1 + QNm - QBm - QDm
B21: QFinal = QExec x FDM
